Workbook
Name Excel_BuiltIn__FilterDatabase: 'Декретчицы'!$B$4:$N$5
Name Excel_BuiltIn__FilterDatabase: 'Инвалиды'!$A$4:$H$4
Name Excel_BuiltIn__FilterDatabase: 'Нетрудоспособность '!$A$2:$L$2
Name Excel_BuiltIn__FilterDatabase: 'Список сотрудников'!$A$2:$AO$2
Name Excel_BuiltIn__FilterDatabase: 'Список уволенных'!$A$2:$W$2
Name Excel_BuiltIn__FilterDatabase: 'Справочник'!$A$1:$E$143
Name Excel_BuiltIn__FilterDatabase: 'Срочники'!$A$4:$I$4
Name Excel_BuiltIn__FilterDatabase: 'Текучесть'!$A$2:$AR$10
Name Вид_занятости: 'Вып_списки'!$H$2:$H$3
Name Вид_обучения: 'Вып_списки'!$M$2:$M$3
Name Город: 'Вып_списки'!$F$2:$F$12
Name Категория_должности: 'Вып_списки'!$E$2:$E$7
Name Компания: 'Вып_списки'!$B$2:$B$8
Name Месяц: 'Вып_списки'!$A$2:$A$13
Name Направление_обучения: 'Вып_списки'!$N$2:$N$4
Name Приоритет_закрытия: 'Вып_списки'!$P$2:$P$4
Name Причина_нетрудоспособности: 'Вып_списки'!$L$2:$L$8
Name Причины_изменения: 'Вып_списки'!$J$2:$J$11
Name Причины_невключения: 'Вып_списки'!$I$2:$I$10
Name Продуктивный: 'Вып_списки'!$O$2:$O$3
Name Рабочий_день: 'Вып_списки'!$D$2:$D$4
Name Расшифровка_статей_увольнения: 'Расшифровка статей увольнения'!$B$2:$B$36
Name Реальные_причины_увольнения: 'Реальные причины увольнения'!$A$2:$A$29
Name Статьи_увольнения: 'Расшифровка статей увольнения'!$A$2:$A$36
Name Тип_договора: 'Вып_списки'!$C$2:$C$3
Name Функция: 'Вып_списки'!$G$2:$G$6
Name ЦФО: 'Вып_списки'!$R$2:$R$24

Sheet Инструкция
A1: Инструкция по заполнению отчета
A4: Отчет заполняется на ежемесячной основе в 1 рабочий день месяца, следующего за отчетным
A5: Все листы, кроме "Список сотрудников" заполняются нарастающим итогом с начала года
A6: Лист "Список сотрудников" заполняются на последний календарный день месяца
A8: Лист "Список сотрудников" | B8: Заполняется вручную
A9: Ежемесячно отражается численность работающих сотрудников (списочная) на последнюю дату месяца, включая своместителей, декретчиц, прогульщиков и т.д.
A10: за ИСКЮЧЕНИЕМ (не включаем):
A11: − сотрудники, находящиеся на декретном больничном листе
A12: − сотрудники, находящихся в отпуске по уходу за ребенком (до 1,5 или до 3 лет)
A13: − сотрудники с длительным прогулом или с длительным невыясненным отсутствием
A14: − сотрудники, находящиеся в длительном (3 месяца и более) отпуске без сохранения заработной платы
A15: − внутренние совместители (по той должности, которая является для них работой по совместительству)
A16: Сотрудники, уволенные в последний календарный день месяца включаются на оба листа: и в численность, и в уволенные
A17: Лист "Список сотрудников" в шаблоне | B17: Комментарии по данным для отчета
A18: Таб.№ | B18: табельный номер сотрудника
A19: ФИО | B19: ФИО сотрудника
A20: Дата начала работы в ГК (при переводе из одного юрлица в другое) | B20: первичная дата приема на работу (при переводе внутри ГК)
A21: Дата начала работы в юрлице | B21: дата начала работы в юрлице
A22: Дата рождения | B22: дата рождения
A23: Подразделение | B23: Наименование подразделения
A24: Должность | B24: Наименование должности
A25: Пол сотрудника | B25: Пол сотрудника
A26: Категория персонала | B26: Категория персонала: см.лист "Справочник"
A27: Город, фактическое место работы | B27: Наименование места работы сотрудника (название города).
A28: полный \ неполный рабочий день | B28: полный – для сотрудников, работающих полный рабочий день Не полный – для сотрудников, работающих не полный рабочий день
... A30: Основное место работы/Совместительство | B30: Вид работы основной или совместитель
A31: Включаем \ не включаем в отчет
A32: Причина невключения сотрудника в отчет | B32: см.список исключений выше
A33: Функция | B33: Функция к которой относиться сотрудник
A34: Месяц | B34: месяц, за который предоставляется отчет
A35: Изменение поля "включаем/не включаем"
A36: Причина изменения "включаем/не включаем" | B36: см.список исключений выше (если в течении отчетного месяца изменился статус сотрудника)
A37: Юридическое лицо | B37: Юридическое лицо
A39: Лист "Список уволенных" | B39: Заполняется вручную
A40: Лист "Список уволенных" в шаблоне | B40: Комментарии по данным для отчета
A41: Таб. № | B41: табельный номер сотрудника
A42: ФИО | B42: ФИО сотрудника
A43: Подразделение | B43: Наименование должности
A44: Должность | B44: Вид работы основной или совместитель
A45: Функция | B45: не заполняем
...

Sheet Справочник
A1: Подразделение | B1: Должность | C1: Категория персонала | D1: Продуктивность | E1: Функция | F1: Город | G1: Уровень управления | H1: ЦФО
A2: Административно-хозяйственный отдел | B2: Уборщик помещений | C2: рабочий | D2: Не продуктивный | E2: Вспомогательные | F2: Ростов-на-Дону | G2: 7ПП | H2: ЦФО Служба логистики (2 ур)
A3: Администрация | B3: Директор | C3: директор | D3: Не продуктивный | E3: Вспомогательные | F3: Ростов-на-Дону | G3: 2БП | H3: ЦФО Амурская легенда (1 ур)
A4: Азовский СЦ | B4: Кассир-приемщик | C4: служащий | D4: Продуктивный | E4: Сервис | F4: Азов | G4: 7БП | H4: ЦФО МГС (1 ур)
A5: Азовский СЦ | B5: Начальник сервисного центра | C5: руководитель отдела | D5: Продуктивный | E5: Сервис | F5: Азов | G5: 5БП | H5: ЦФО МГС (1 ур)
A6: Аксайский СЦ | B6: Начальник сервисного центра | C6: руководитель отдела | D6: Продуктивный | E6: Сервис | F6: Аксай | G6: 5БП | H6: ЦФО МГС (1 ур)
A7: Аксайский СЦ | B7: Техник | C7: рабочий | D7: Продуктивный | E7: Сервис | F7: Аксай | G7: 7БП | H7: ЦФО МГС (1 ур)
A8: Батайский СЦ | B8: Кассир-приемщик | C8: служащий | D8: Продуктивный | E8: Сервис | F8: Батайск | G8: 7БП | H8: ЦФО МГС (1 ур)
A9: Батайский СЦ | B9: Начальник сервисного центра | C9: руководитель отдела | D9: Продуктивный | E9: Сервис | F9: Батайск | G9: 5БП | H9: ЦФО МГС (1 ур)
A10: Бухгалтерия | B10: Бухгалтер по расчету заработной платы | C10: специалист | D10: Не продуктивный | E10: Вспомогательные | F10: Ростов-на-Дону | G10: 6ПП | H10: ЦФО Финслужба (2 ур)
A11: Бухгалтерия | B11: Заместитель главного бухгалтера | C11: специалист | D11: Не продуктивный | E11: Вспомогательные | F11: Ростов-на-Дону | G11: 5ПП | H11: ЦФО Финслужба (2 ур)
A12: Бухгалтерия | B12: Помощник бухгалтера | C12: служащий | D12: Не продуктивный | E12: Вспомогательные | F12: Ростов-на-Дону | G12: 6ПП | H12: ЦФО Финслужба (2 ур)
... A170: Руководство | B170: Председатель совета директоров | C170: директор | D170: Не продуктивный | E170: Вспомогательные | F170: Ростов-на-Дону | G170: 1БП | H170: ЦФО Руководство (2 ур)
A171: Руководство | B171: Сборщик | C171: рабочий | D171: Продуктивный | E171: Производство | F171: Ростов-на-Дону | G171: 7БП
A172: Руководство | B172: Финансовый директор | C172: директор направления | D172: Не продуктивный | E172: Вспомогательные | F172: Ростов-на-Дону | G172: 2ПП | H172: ЦФО Руководство (2 ур)
A173: Руководство (основное) | B173: Директор | C173: директор | D173: Не продуктивный | E173: Вспомогательные | F173: Ростов-на-Дону | G173: 2БП | H173: ЦФО МГС (1 ур)
A174: Руководство конструкторского бюро | B174: Директор по научной работе | C174: директор направления | D174: Не продуктивный | E174: Вспомогательные | F174: Ростов-на-Дону | G174: 1ПП | H174: ЦФО Руководство (2 ур)
A175: Руководство конструкторского бюро | B175: Заместитель главного бухгалтера | C175: специалист | D175: Не продуктивный | E175: Вспомогательные | F175: Ростов-на-Дону | G175: 5ПП | H175: ЦФО Финслужба (2 ур)
A176: Руководство конструкторского бюро | B176: Технический директор | C176: директор направления | D176: Не продуктивный | E176: Вспомогательные | F176: Ростов-на-Дону | G176: 3ПП | H176: ЦФО Производство БМИ (1 ур)
A177: Сальский СЦ | B177: Кассир-приемщик | C177: служащий | D177: Продуктивный | E177: Сервис | F177: Сальск | G177: 7БП | H177: ЦФО МГС (1 ур)
A178: Сальский СЦ | B178: Начальник сервисного центра | C178: руководитель отдела | D178: Продуктивный | E178: Сервис | F178: Сальск | G178: 5БП | H178: ЦФО МГС (1 ур)
A179: Сальский СЦ | B179: Техник | C179: рабочий | D179: Продуктивный | E179: Сервис | F179: Сальск | G179: 7БП | H179: ЦФО МГС (1 ур)
A180: Сборочный участок №1 | B180: Инженер-электроник | C180: специалист | D180: Продуктивный | E180: Производство | F180: Ростов-на-Дону | G180: 6БП | H180: ЦФО Производство №1 (1 ур)
A181: Сборочный участок №1 | B181: Мастер участка | C181: руководитель отдела | D181: Не продуктивный | E181: Производство | F181: Ростов-на-Дону | G181: 5ПП | H181: ЦФО Производство №1 (1 ур)
A182: Сборочный участок №1 | B182: Регулировщик радиоэлектронной аппаратуры и приборов | C182: рабочий | D182: Продуктивный | E182: Производство | F182: Ростов-на-Дону | G182: 7БП | H182: ЦФО Производство №1 (1 ур)
A183: Сборочный участок №1 | B183: Слесарь-сборщик радиоэлектронной аппаратуры | C183: рабочий | D183: Продуктивный | E183: Производство | F183: Ростов-на-Дону | G183: 7БП | H183: ЦФО Производство №1 (1 ур)
... A313: Участок сборки счетчиков | B313: Монтажник | C313: рабочий | D313: Продуктивный | E313: Производство | F313: Ростов-на-Дону | G313: 7БП | H313: ЦФО Производство №2 (1 ур)
A314: Отдел материально-технического обеспечения | B314: Старший оператор 1С

Sheet Вып_списки
A1: Месяц | B1: Компания | C1: Тип договора | D1: Рабочий день | E1: категория персонала | F1: Город, фактическое место работы | G1: Функции | H1: Вид занятости | I1: причины невключения | J1: причины изменения | L1: причина нетрудоспособности | M1: Вид обучения | N1: Направление обучения | O1: Продуктивность | P1: Приоритет закрытия | Q1: Вид приема | R1: ЦФО
A2: Январь | B2: АЛМАЗ | C2: постоянный | D2: полный | E2: директор | F2: Ростов-на-Дону | G2: Продажи | H2: Основное место | I2: отпуск по беременности и родам (Декрет) | J2: уход в отпуск по беременности и родам | K2: стал исключаем | L2: заболевание | M2: Внутренее | N2: Профессиональное | O2: Продуктивный | P2: Первоочередная | Q2: Перевод | R2: ЦФО Амурская легенда (1 ур)
A3: Февраль | B3: Метрогазсервис | C3: временный | D3: неполный | E3: директор направления | F3: Азов | G3: Производство | H3: Совместительство | I3: отпуск по уходу за ребенком до 1,5 и 3-х лет | J3: уход в отпуск по уходу за ребенком до 1,5 и 3-х лет | K3: стал исключаем | L3: уход за больным членом семьи | M3: Внешнее | N3: Личностное | O3: Не продуктивный | P3: Текущая | Q3: Подбор | R3: ЦФО Главный метролог (1 ур)
A4: Март | B4: НПО Турбулентность-Дон | D4: сокращенный | E4: руководитель отдела | F4: Аксай | G4: Вспомогательные | I4: длительный прогул | J4: начало длительного прогула | K4: стал исключаем | L4: травма | N4: Разрешительные документы | P4: Резерв | Q4: Приведи друга | R4: ЦФО Директор НПО (2 ур)
A5: Апрель | B5: ИП Корниенко М.С. | E5: специалист | F5: Батайск | G5: Сервис | I5: длительное отсутствие по невыясненным причинам | J5: начало длительного отсутствие по невыясненным причинам | K5: стал исключаем | L5: отпуск по беременности и родам | R5: ЦФО КБ (2 ур)
A6: Май | B6: Амурская легенда | E6: служащий | F6: Волгодонск | G6: Логистика | I6: длительный отпуск без сохранения з/п | J6: уход в отпуск без сохранения з/п | K6: стал исключаем | L6: протезирование в стационаре | R6: ЦФО Ком.служба (2 ур)
A7: Июнь | B7: Милака | E7: рабочий | F7: Каменск-Шахтинск | I7: длительный больничный | J7: выход из отпуска по беременности и родам | K7: стал включаем | L7: долечивание в санатории | R7: ЦФО МГС (1 ур)
A8: Июль | F8: Новочеркасск | I8: внутренний соместитель | J8: выход из отпуска по уходу за ребенком до 1,5 и 3-х лет | K8: стал включаем | L8: иное состояние | R8: ЦФО Милака (1 ур)
A9: Август | F9: Таганрог | I9: внешний совместитель | J9: конец длительного прогула | K9: стал включаем | R9: ЦФО Производство №1 (1 ур)
A10: Сентябрь | F10: Шахты | I10: мобилизация | J10: конец длительного отсутствие по невыясненным причинам | K10: стал включаем | R10: ЦФО Производство №2 (1 ур)
A11: Октябрь | F11: Сальск | J11: выход из отпуска без сохранения з/п | K11: стал включаем | R11: ЦФО Производство БМИ (1 ур)
A12: Ноябрь | F12: Миллерово | R12: ЦФО Руководство (2 ур)
A13: Декабрь | R13: ЦФО Сервисная служба (1+2 ур)
R14: ЦФО Служба безопасности (2 ур)
R15: ЦФО Служба технического директора (2 ур)
R16: ЦФО Служба развития (2 ур)
R17: ЦФО Служба логистики (2 ур)
R18: ЦФО Экспериментальный цех (2 ур)
R19: ЦФО Служба автоматизации (2 ур)

Sheet Список сотрудников
A1: Выгрузка из 1С | B1: Выгрузка из 1С | C1: Заполняется вручную | D1: Выгрузка из 1С | E1: Выгрузка из 1С | F1: Выгрузка из 1С | G1: Выгрузка из 1С | H1: Заполняется автоматически | I1: Заполняется автоматически | J1: Заполняется автоматически | K1: Заполняем вручную, настроен выпадающий список | L1: Заполняется автоматически | M1: Заполняется автоматически | N1: Выгрузка из 1С | O1: Выгрузка из 1С | P1: Выгрузка из 1С | Q1: Заполняется автоматически | R1: Заполняем вручную, настроен выпадающий список | S1: Заполняется автоматически | T1: Заполняем вручную, настроен выпадающий список | U1: Заполняется автоматически | V1: Заполняем вручную, настроен выпадающий список | W1: Заполняется автоматически | AB1: стаж работы в компании | AJ1: возраст
A2: Таб.№ | B2: ФИО | C2: Дата начала работы в ГК (при переводе из одного юрлица в другое) | D2: Дата начала работы в юрлице | E2: Дата рождения | F2: Подразделение | G2: Должность | H2: Пол сотрудника | I2: Категория персонала | J2: Уровень управления | K2: ЦФО | L2: Продуктивность | M2: Город, фактическое место работы | N2: полный \ неполный рабочий день | O2: Ставка | P2: Основное место работы/Совместительство | Q2: Включаем \ не включаем в отчет | R2: Причина невключения сотрудника в отчет | S2: Функция | T2: Месяц | U2: Изменение поля "включаем/не включаем" | V2: Юридическое лицо | W2: Сегодня | AB2: лет | AC2: месяцев | AD2: дней | AJ2: лет | AK2: месяцев | AL2: дней
A3: 00506 | B3: Мегрелишвили Михаил Эмзарович | D3: 29.01.2026 | E3: 27.05.1984 | F3: Руководство (основное) | G3: Директор | H3: =IF(ISBLANK(B3),"-",IF(ISERROR(FIND("вич",B3,1)),"ж","м")) -> м | I3: #REF! | J3: #REF! | K3: ЦФО Производство №2 (1 ур) | O3: 3/10 | P3: Внешнее совместительство | Q3: =IF(R3="","включаем","не включаем") -> не включаем | R3: внешний совместитель | T3: Май | V3: АЛМАЗ ООО | W3: 46173
A4: 00436 | B4: Павлова Лариса Викторовна | D4: 01.04.2024 | E4: 20.04.1976 | F4: Руководство | G4: Главный бухгалтер | H4: =IF(ISBLANK(B4),"-",IF(ISERROR(FIND("вич",B4,1)),"ж","м")) -> ж | I4: #REF! | J4: #REF! | K4: ЦФО Производство №2 (1 ур) | O4: 1 | P4: Основное место работы | Q4: =IF(R4="","включаем","не включаем") -> включаем | T4: Май | V4: АЛМАЗ ООО | W4: 46173
A5: 00238 | B5: Лазарева Марина Владимировна | D5: 02.08.2021 | E5: 13.10.1983 | F5: Руководство | G5: Бухгалтер | H5: =IF(ISBLANK(B5),"-",IF(ISERROR(FIND("вич",B5,1)),"ж","м")) -> ж | I5: #REF! | J5: #REF! | K5: ЦФО Производство №2 (1 ур) | O5: 1 | P5: Внешнее совместительство | Q5: =IF(R5="","включаем","не включаем") -> не включаем | R5: внешний совместитель | T5: Май | V5: АЛМАЗ ООО | W5: 46173
A6: 00407 | B6: Полякова Кристина Валентиновна | D6: 17.07.2023 | E6: 05.09.1983 | F6: Производство №2 | G6: Инженер по подготовке производства | H6: =IF(ISBLANK(B6),"-",IF(ISERROR(FIND("вич",B6,1)),"ж","м")) -> ж | I6: #REF! | J6: #REF! | K6: ЦФО Производство №2 (1 ур) | O6: 1 | P6: Основное место работы | Q6: =IF(R6="","включаем","не включаем") -> включаем | T6: Май | V6: АЛМАЗ ООО | W6: 46173
A7: 00495 | B7: Цимбалова Любовь Витальевна | D7: 22.07.2025 | E7: 10.12.1995 | F7: Производство №2 | G7: Диспетчер 1С ERP | H7: =IF(ISBLANK(B7),"-",IF(ISERROR(FIND("вич",B7,1)),"ж","м")) -> ж | I7: #REF! | J7: #REF! | K7: ЦФО Производство №2 (1 ур) | O7: 1 | P7: Основное место работы | Q7: =IF(R7="","включаем","не включаем") -> включаем | T7: Май | V7: АЛМАЗ ООО | W7: 46173
A8: 00510 | B8: Сорокина Светлана Петровна | D8: 15.05.2026 | E8: 19.07.1963 | F8: Производство №2 | G8: Специалист по управлению товарными запасами | H8: =IF(ISBLANK(B8),"-",IF(ISERROR(FIND("вич",B8,1)),"ж","м")) -> ж | I8: #REF! | J8: #REF! | K8: ЦФО Производство №2 (1 ур) | O8: 1 | P8: Основное место работы | Q8: =IF(R8="","включаем","не включаем") -> включаем | T8: Май | V8: АЛМАЗ ООО | W8: 46173
A9: 0000000038 | B9: Оганесян Кристина Лазаревна | D9: 01.04.2016 | E9: 13.03.1981 | F9: Участок сборки счетчиков | G9: Бригадир сборщиков | H9: =IF(ISBLANK(B9),"-",IF(ISERROR(FIND("вич",B9,1)),"ж","м")) -> ж | I9: #REF! | J9: #REF! | K9: ЦФО Производство №2 (1 ур) | O9: 1 | P9: Основное место работы | Q9: =IF(R9="","включаем","не включаем") -> включаем | T9: Май | V9: АЛМАЗ ООО | W9: 46173
A10: 00201 | B10: Подгорная Олеся Владимировна | D10: 23.09.2020 | E10: 20.10.1983 | F10: Участок сборки счетчиков | G10: Бригадир сборщиков | H10: =IF(ISBLANK(B10),"-",IF(ISERROR(FIND("вич",B10,1)),"ж","м")) -> ж | I10: #REF! | J10: #REF! | K10: ЦФО Производство №2 (1 ур) | O10: 1 | P10: Основное место работы | Q10: =IF(R10="","включаем","не включаем") -> включаем | T10: Май | V10: АЛМАЗ ООО | W10: 46173
A11: 00468 | B11: Беседин Вадим Вадимович | D11: 03.03.2025 | E11: 10.05.1979 | F11: Участок сборки счетчиков | G11: Сборщик | H11: =IF(ISBLANK(B11),"-",IF(ISERROR(FIND("вич",B11,1)),"ж","м")) -> м | I11: #REF! | J11: #REF! | K11: ЦФО Производство №2 (1 ур) | O11: 1 | P11: Основное место работы | Q11: =IF(R11="","включаем","не включаем") -> включаем | T11: Май | V11: АЛМАЗ ООО | W11: 46173
A12: 00489 | B12: Богачева Алла Александровна | D12: 01.07.2025 | E12: 26.07.1981 | F12: Участок сборки счетчиков | G12: Сборщик | H12: =IF(ISBLANK(B12),"-",IF(ISERROR(FIND("вич",B12,1)),"ж","м")) -> ж | I12: #REF! | J12: #REF! | K12: ЦФО Производство №2 (1 ур) | O12: 1 | P12: Основное место работы | Q12: =IF(R12="","включаем","не включаем") -> включаем | T12: Май | V12: АЛМАЗ ООО | W12: 46173
A13: 00483 | B13: Добровольская Людмила Николаевна | D13: 27.05.2025 | E13: 23.08.1981 | F13: Участок сборки счетчиков | G13: Сборщик | H13: =IF(ISBLANK(B13),"-",IF(ISERROR(FIND("вич",B13,1)),"ж","м")) -> ж | I13: #REF! | J13: #REF! | K13: ЦФО Производство №2 (1 ур) | O13: 1 | P13: Основное место работы | Q13: =IF(R13="","включаем","не включаем") -> включаем | T13: Май | V13: АЛМАЗ ООО | W13: 46173
A14: 00416 | B14: Земляков Василий Владимирович | D14: 22.09.2023 | E14: 08.04.1972 | F14: Участок сборки счетчиков | G14: Сборщик | H14: =IF(ISBLANK(B14),"-",IF(ISERROR(FIND("вич",B14,1)),"ж","м")) -> м | I14: #REF! | J14: #REF! | K14: ЦФО Производство №2 (1 ур) | O14: 1 | P14: Основное место работы | Q14: =IF(R14="","включаем","не включаем") -> включаем | T14: Май | V14: АЛМАЗ ООО | W14: 46173
A15: 00499 | B15: Зимовец Полина Александровна | D15: 21.10.2025 | E15: 09.02.2004 | F15: Участок сборки счетчиков | G15: Сборщик | H15: =IF(ISBLANK(B15),"-",IF(ISERROR(FIND("вич",B15,1)),"ж","м")) -> ж | I15: #REF! | J15: #REF! | K15: ЦФО Производство №2 (1 ур) | O15: 1 | P15: Основное место работы | Q15: =IF(R15="","включаем","не включаем") -> включаем | T15: Май | V15: АЛМАЗ ООО | W15: 46173
A16: 00487 | B16: Кейсон Алексея Викторовна | D16: 01.07.2025 | E16: 24.12.2000 | F16: Участок сборки счетчиков | G16: Сборщик | H16: =IF(ISBLANK(B16),"-",IF(ISERROR(FIND("вич",B16,1)),"ж","м")) -> ж | I16: #REF! | J16: #REF! | K16: ЦФО Производство №2 (1 ур) | O16: 1 | P16: Основное место работы | Q16: =IF(R16="","включаем","не включаем") -> включаем | T16: Май | V16: АЛМАЗ ООО | W16: 46173
A17: 00421 | B17: Кобцева Наталья Алексеевна | D17: 04.10.2023 | E17: 09.05.1977 | F17: Участок сборки счетчиков | G17: Сборщик | H17: =IF(ISBLANK(B17),"-",IF(ISERROR(FIND("вич",B17,1)),"ж","м")) -> ж | I17: #REF! | J17: #REF! | K17: ЦФО Производство №2 (1 ур) | O17: 1 | P17: Основное место работы | Q17: =IF(R17="","включаем","не включаем") -> включаем | T17: Май | V17: АЛМАЗ ООО | W17: 46173
... A21: 00511 | B21: Свистов Максим Вячеславович | D21: 18.05.2026 | E21: 14.01.1975 | F21: Участок сборки счетчиков | G21: Сборщик | H21: =IF(ISBLANK(B21),"-",IF(ISERROR(FIND("вич",B21,1)),"ж","м")) -> м | I21: #REF! | J21: #REF! | K21: ЦФО Производство №2 (1 ур) | O21: 1 | P21: Основное место работы | Q21: =IF(R21="","включаем","не включаем") -> включаем | T21: Май | V21: АЛМАЗ ООО | W21: 46173
A22: 00478 | B22: Фомина Алена Игоревна | D22: 12.05.2025 | E22: 18.10.1996 | F22: Участок сборки счетчиков | G22: Сборщик | H22: =IF(ISBLANK(B22),"-",IF(ISERROR(FIND("вич",B22,1)),"ж","м")) -> ж | I22: #REF! | J22: #REF! | K22: ЦФО Производство №2 (1 ур) | O22: 1 | P22: Основное место работы | Q22: =IF(R22="","включаем","не включаем") -> не включаем | R22: отпуск по беременности и родам (Декрет) | T22: Май | V22: АЛМАЗ ООО | W22: 46173
A23: 00486 | B23: Азриян Артур Ашотович | D23: 09.06.2025 | E23: 14.04.1999 | F23: Участок сборки счетчиков | G23: Мастер участка | H23: =IF(ISBLANK(B23),"-",IF(ISERROR(FIND("вич",B23,1)),"ж","м")) -> м | I23: #REF! | J23: #REF! | K23: ЦФО Производство №2 (1 ур) | O23: 1 | P23: Основное место работы | Q23: =IF(R23="","включаем","не включаем") -> включаем | T23: Май | V23: АЛМАЗ ООО | W23: 46173
A24: 00497 | B24: Сафронов Игорь Александрович | D24: 01.09.2025 | E24: 12.03.1992 | F24: Участок сборки счетчиков | G24: Мастер участка | H24: =IF(ISBLANK(B24),"-",IF(ISERROR(FIND("вич",B24,1)),"ж","м")) -> м | I24: #REF! | J24: #REF! | K24: ЦФО Производство №2 (1 ур) | O24: 1 | P24: Основное место работы | Q24: =IF(R24="","включаем","не включаем") -> включаем | T24: Май | V24: АЛМАЗ ООО | W24: 46173
A25: 00419 | B25: Андреев Артем Евгеньевич | D25: 28.09.2023 | E25: 12.07.2002 | F25: Участок СПУ-5 | G25: Бригадир участка | H25: =IF(ISBLANK(B25),"-",IF(ISERROR(FIND("вич",B25,1)),"ж","м")) -> м | I25: #REF! | J25: #REF! | K25: ЦФО Производство №2 (1 ур) | O25: 1 | P25: Основное место работы | Q25: =IF(R25="","включаем","не включаем") -> включаем | T25: Май | V25: АЛМАЗ ООО | W25: 46173
A26: 00496 | B26: Клюшник Сергей Романович | D26: 01.08.2025 | E26: 07.10.2004 | F26: Участок СПУ-5 | G26: Слесарь-калибровщик | H26: =IF(ISBLANK(B26),"-",IF(ISERROR(FIND("вич",B26,1)),"ж","м")) -> м | I26: #REF! | J26: #REF! | K26: ЦФО Производство №2 (1 ур) | O26: 1 | P26: Основное место работы | Q26: =IF(R26="","включаем","не включаем") -> включаем | T26: Май | V26: АЛМАЗ ООО | W26: 46173
A27: 0000000044 | B27: Сокол Рита Васильевна | D27: 01.04.2016 | E27: 25.06.1963 | F27: Участок упаковки | G27: Сборщик-упаковщик | H27: =IF(ISBLANK(B27),"-",IF(ISERROR(FIND("вич",B27,1)),"ж","м")) -> ж | I27: #REF! | J27: #REF! | K27: ЦФО Производство №2 (1 ур) | O27: 1 | P27: Основное место работы | Q27: =IF(R27="","включаем","не включаем") -> включаем | T27: Май | V27: АЛМАЗ ООО | W27: 46173
A28: 00166 | B28: Сухарева Ольга Андреевна | D28: 22.10.2019 | E28: 24.07.1961 | F28: Участок упаковки | G28: Сборщик-упаковщик | H28: =IF(ISBLANK(B28),"-",IF(ISERROR(FIND("вич",B28,1)),"ж","м")) -> ж | I28: #REF! | J28: #REF! | K28: ЦФО Производство №2 (1 ур) | O28: 1 | P28: Основное место работы | Q28: =IF(R28="","включаем","не включаем") -> включаем | T28: Май | V28: АЛМАЗ ООО | W28: 46173
A29: 00163 | B29: Тарасов Василий Михайлович | D29: 26.09.2019 | E29: 19.01.1984 | F29: Участок ремонта гарантийных приборов | G29: Сборщик | H29: =IF(ISBLANK(B29),"-",IF(ISERROR(FIND("вич",B29,1)),"ж","м")) -> м | I29: #REF! | J29: #REF! | K29: ЦФО Производство №2 (1 ур) | O29: 1 | P29: Основное место работы | Q29: =IF(R29="","включаем","не включаем") -> включаем | T29: Май | V29: АЛМАЗ ООО | W29: 46173
A30: 00488 | B30: Очнев Олег Юрьевич | D30: 01.07.2025 | E30: 07.02.1972 | F30: Участок ремонта гарантийных приборов | G30: Монтажник РЭА | H30: =IF(ISBLANK(B30),"-",IF(ISERROR(FIND("вич",B30,1)),"ж","м")) -> м | I30: #REF! | J30: #REF! | K30: ЦФО Производство №2 (1 ур) | O30: 1 | P30: Основное место работы | Q30: =IF(R30="","включаем","не включаем") -> включаем | T30: Май | V30: АЛМАЗ ООО | W30: 46173
A31: 00512 | B31: Гладуненко Павел Александрович | D31: 19.05.2026 | E31: 18.12.1980 | F31: Участок монтажа радиоэлектронной аппаратуры | G31: Монтажник РЭА | H31: =IF(ISBLANK(B31),"-",IF(ISERROR(FIND("вич",B31,1)),"ж","м")) -> м | I31: #REF! | J31: #REF! | K31: ЦФО Производство №2 (1 ур) | O31: 1 | P31: Основное место работы | Q31: =IF(R31="","включаем","не включаем") -> включаем | T31: Май | V31: АЛМАЗ ООО | W31: 46173
A32: 00449 | B32: Добровольский Дмитрий Дмитриевич | D32: 01.08.2024 | E32: 05.07.1984 | F32: Участок ремонта и обслуживания оборудования | G32: Бригадир участка | H32: =IF(ISBLANK(B32),"-",IF(ISERROR(FIND("вич",B32,1)),"ж","м")) -> м | I32: #REF! | J32: #REF! | K32: ЦФО Производство №2 (1 ур) | O32: 1 | P32: Основное место работы | Q32: =IF(R32="","включаем","не включаем") -> включаем | T32: Май | V32: АЛМАЗ ООО | W32: 46173
A33: 00443 | B33: Андронов Николай Леонидович | D33: 14.06.2024 | E33: 01.09.1988 | F33: Участок ремонта и обслуживания оборудования | G33: Слесарь КИПиА | H33: =IF(ISBLANK(B33),"-",IF(ISERROR(FIND("вич",B33,1)),"ж","м")) -> м | I33: #REF! | J33: #REF! | K33: ЦФО Производство №2 (1 ур) | O33: 1 | P33: Основное место работы | Q33: =IF(R33="","включаем","не включаем") -> включаем | T33: Май | V33: АЛМАЗ ООО | W33: 46173
A34: 00221 | B34: Кравченко Александр Борисович | D34: 30.04.2021 | E34: 12.04.1971 | F34: Участок ремонта и обслуживания оборудования | G34: Слесарь КИПиА | H34: =IF(ISBLANK(B34),"-",IF(ISERROR(FIND("вич",B34,1)),"ж","м")) -> м | I34: #REF! | J34: #REF! | K34: ЦФО Производство №2 (1 ур) | O34: 1 | P34: Основное место работы | Q34: =IF(R34="","включаем","не включаем") -> включаем | T34: Май | V34: АЛМАЗ ООО | W34: 46173
... A41: 0000000004 | B41: Кулешова Наталья Станиславовна | D41: 03.10.2016 | E41: 05.11.1984 | F41: Отдел материально-технического обеспечения | G41: Заместитель начальника отдела | H41: =IF(ISBLANK(B41),"-",IF(ISERROR(FIND("вич",B41,1)),"ж","м")) -> ж | I41: #REF! | J41: #REF! | K41: ЦФО Служба логистики (2 ур) | O41: 1 | P41: Основное место работы | Q41: =IF(R41="","включаем","не включаем") -> включаем | T41: Май | V41: ИП Корниенко М.В. | W41: 46173
A42: 00029 | B42: Дмитрук Оксана Александровна | D42: 14.08.2023 | E42: 21.02.1985 | F42: Отдел материально-технического обеспечения | G42: Менеджер по сопровождению | H42: =IF(ISBLANK(B42),"-",IF(ISERROR(FIND("вич",B42,1)),"ж","м")) -> ж | I42: #REF! | J42: #REF! | K42: ЦФО Служба логистики (2 ур) | O42: 1 | P42: Основное место работы | Q42: =IF(R42="","включаем","не включаем") -> не включаем | R42: отпуск по беременности и родам (Декрет) | T42: Май | V42: ИП Корниенко М.В. | W42: 46173
A43: 00043 | B43: Ковалева Вера Александровна | D43: 02.02.2026 | E43: 13.05.1997 | F43: Отдел материально-технического обеспечения | G43: Менеджер по сопровождению | H43: =IF(ISBLANK(B43),"-",IF(ISERROR(FIND("вич",B43,1)),"ж","м")) -> ж | I43: #REF! | J43: #REF! | K43: ЦФО Служба логистики (2 ур) | O43: 1 | P43: Основное место работы | Q43: =IF(R43="","включаем","не включаем") -> включаем | T43: Май | V43: ИП Корниенко М.В. | W43: 46173
A44: 00044 | B44: Любченко Оксана Николаевна | D44: 18.05.2026 | E44: 26.03.1976 | F44: Отдел материально-технического обеспечения | G44: Менеджер по сопровождению | H44: =IF(ISBLANK(B44),"-",IF(ISERROR(FIND("вич",B44,1)),"ж","м")) -> ж | I44: #REF! | J44: #REF! | K44: ЦФО Служба логистики (2 ур) | O44: 1 | P44: Основное место работы | Q44: =IF(R44="","включаем","не включаем") -> включаем | T44: Май | V44: ИП Корниенко М.В. | W44: 46173
A45: 00041 | B45: Нижерадзе Алина Геноевна | D45: 10.09.2025 | E45: 18.06.2003 | F45: Отдел материально-технического обеспечения | G45: Менеджер по сопровождению | H45: =IF(ISBLANK(B45),"-",IF(ISERROR(FIND("вич",B45,1)),"ж","м")) -> ж | I45: #REF! | J45: #REF! | K45: ЦФО Служба логистики (2 ур) | O45: 1 | P45: Основное место работы | Q45: =IF(R45="","включаем","не включаем") -> включаем | T45: Май | V45: ИП Корниенко М.В. | W45: 46173
A46: 00013 | B46: Пожидаева Марина Васильевна | D46: 19.04.2021 | E46: 21.10.1981 | F46: Отдел материально-технического обеспечения | G46: Менеджер по сопровождению | H46: =IF(ISBLANK(B46),"-",IF(ISERROR(FIND("вич",B46,1)),"ж","м")) -> ж | I46: #REF! | J46: #REF! | K46: ЦФО Служба логистики (2 ур) | O46: 1 | P46: Основное место работы | Q46: =IF(R46="","включаем","не включаем") -> включаем | T46: Май | V46: ИП Корниенко М.В. | W46: 46173
A47: 00038 | B47: Коваленко Артемий Олегович | D47: 05.11.2024 | E47: 09.08.1979 | F47: Отдел материально-технического обеспечения | G47: Начальник отдела материально-технического обеспечения | H47: =IF(ISBLANK(B47),"-",IF(ISERROR(FIND("вич",B47,1)),"ж","м")) -> м | I47: #REF! | J47: #REF! | K47: ЦФО Служба логистики (2 ур) | O47: 1 | P47: Основное место работы | Q47: =IF(R47="","включаем","не включаем") -> включаем | T47: Май | V47: ИП Корниенко М.В. | W47: 46173
A48: 00006 | B48: Ершова Ирина Лаврентьевна | D48: 26.11.2018 | E48: 21.10.1967 | F48: Отдел материально-технического обеспечения | G48: Ведущий менеджер | H48: =IF(ISBLANK(B48),"-",IF(ISERROR(FIND("вич",B48,1)),"ж","м")) -> ж | I48: #REF! | J48: #REF! | K48: ЦФО Служба логистики (2 ур) | O48: 1 | P48: Основное место работы | Q48: =IF(R48="","включаем","не включаем") -> включаем | T48: Май | V48: ИП Корниенко М.В. | W48: 46173
A49: 0000000003 | B49: Коржов Дмитрий Владимирович | D49: 03.10.2016 | E49: 27.03.1977 | F49: Отдел материально-технического обеспечения | G49: Ведущий менеджер | H49: =IF(ISBLANK(B49),"-",IF(ISERROR(FIND("вич",B49,1)),"ж","м")) -> м | I49: #REF! | J49: #REF! | K49: ЦФО Служба логистики (2 ур) | O49: 1 | P49: Основное место работы | Q49: =IF(R49="","включаем","не включаем") -> включаем | T49: Май | V49: ИП Корниенко М.В. | W49: 46173
...

Sheet Реальные причины увольнения
A1: Реальные причины увольнения
A2: 1. Предложили более высокую позицию, нет карьерного роста в Компании
A3: 1. Недовольство руководством, непосредственным руководителем, общим стилем управления, отношениями в отделе
A4: 1. Другая сфера деятельности, открытие собственного дела и т.п.
A5: 1. Предложили более высокую зарплату на аналогичной должности, неудовлетворенность текущей з/платой
A6: 1. Неудобный график работы
A7: 1. Неудобное расположение, далеко от дома
A8: 1. Плохие условия труда
A9: 1. Состояние здоровья
A10: 1. Учеба/поступление в учебное заведение
A11: 1. Семейные обстоятельства
A12: 1. Переезд офиса/смена адреса
... A29: 3. Уход на пенсию: досрочный/регулярный

Sheet Расшифровка статей увольнения
A1: Расшифровка статей увольнения
A2: п. 1 части 1 ст. 77 ТК РФ | B2: Соглашение сторон
A3: п. 2 части 1 ст. 77 ТК РФ | B3: Истечение срока трудового договора
A4: п. 3 части 1 ст. 77 ТК РФ | B4: Расторжение трудового договора по инициативе работника
A5: п. 5 части 1 ст. 77 ТК РФ | B5: В порядке перевода
A6: п. 6 части 1 ст. 77 ТК РФ | B6: Отказ работника от продолжения работы в связи с изменением подведомственности (подчиненности) организации
A7: п. 6 части 1 ст. 77 ТК РФ | B7: Отказ работника от продолжения работы в связи с реорганизацией организации
A8: п. 6 части 1 ст. 77 ТК РФ | B8: Отказ работника от продолжения работы в связи со сменой собственника имущества организации
A9: п. 7 части 1 ст. 77 ТК РФ | B9: Отказ работника от продолжения работы в связи с изменением определенных сторонами условий трудового договора
A10: п. 8 части 1 ст. 77 ТК РФ | B10: Отсутствие у работодателя работы, необходимой работнику в соответствии с мед. Заключением
A11: п. 9 части 1 ст. 77 ТК РФ | B11: Отказ работника от перевода на работу в другую местность вместе с работодателем
A12: п. 11 части 1 ст. 77 ТК РФ | B12: Нарушение установленных ТК РФ или иным ФЗ правил заключения трудового договора
A13: п. 8 части 1 ст. 77 ТК РФ | B13: Отказ работника от перевода на другую работу, необходимую ему в соответствии с мед. заключением
... A36: ст. 288 ТК РФ | B36: Прием на работу работника, для которого эта работа будет являться основной

Sheet Включаем не включаем
A1: Причина увольнения
A2: Увольнение по собственному желанию | B2: включаем
A3: 1. Предложили более высокую позицию, нет карьерного роста в Компании | B3: включаем
A4: 1. Недовольство руководством, непосредственным руководителем, общим стилем управления, отношениями в отделе | B4: включаем
A5: 1. Другая сфера деятельности, открытие собственного дела и т.п. | B5: включаем
A6: 1. Предложили более высокую зарплату на аналогичной должности, неудовлетворенность текущей з/платой | B6: включаем
A7: 1. Неудобный график работы | B7: включаем
A8: 1. Неудобное расположение, далеко от дома | B8: включаем
A9: 1. Плохие условия труда | B9: включаем
A10: 1. Состояние здоровья | B10: включаем
A11: 1. Учеба/поступление в учебное заведение | B11: включаем
A12: 1. Семейные обстоятельства | B12: включаем
A13: 1. Переезд офиса/смена адреса | B13: включаем
... A32: 3. Уход на пенсию: досрочный/регулярный | B32: не включаем

Sheet Свод по списку
A3: Месяц | B3: (Все)
A4: Включаем \ не включаем в отчет | B4: (несколько элементов)
A5: Причина невключения сотрудника в отчет | B5: (Все)
A7: Количество по полю Юридическое лицо
A8: ЦФО | B8: Подразделение | C8: Итог
A9: ЦФО Амурская легенда (1 ур) | B9: Администрация | C9: 1
B10: Бухгалтерия | C10: 3
B11: ОП Розничная торговая сеть: водный павильон "Западный" | C11: 2
B12: Отдел по работе с клиентами | C12: 1
B13: Отдел продаж | C13: 7
B14: Производственный отдел | C14: 9
B15: Транспортный отдел | C15: 14
A16: ЦФО Амурская легенда (1 ур) Итог | C16: 37
A17: ЦФО Главный метролог (1 ур) | B17: Метрологическая служба | C17: 11
B18: Отдел метрологии и сертификации | C18: 5
B19: Участок ремонта промышленного оборудования | C19: 5
A20: ЦФО Главный метролог (1 ур) Итог | C20: 21
A21: ЦФО Директор НПО (2 ур) | B21: Бухгалтерия | C21: 5
B22: Отдел ценообразования и экономического планирования | C22: 4
B23: Служба управления персоналом | C23: 6
A24: ЦФО Директор НПО (2 ур) Итог | C24: 15
A25: ЦФО КБ (2 ур) | B25: Конструкторское бюро | C25: 10
B26: Конструкторско-технологический отдел | C26: 3
B27: Отдел разработки ПО и АСУ | C27: 2
A28: ЦФО КБ (2 ур) Итог | C28: 15
A29: ЦФО Ком.служба (2 ур) | B29: Отдел внешнеэкономической деятельности | C29: 4
B30: Отдел дилерских продаж | C30: 9
B31: Отдел по продаже БМИ | C31: 4
B32: Отдел по работе с ключевыми клиентами | C32: 5
B33: Отдел по работе с ПАО Газпром | C33: 3
B34: Отдел продаж эталонного оборудования и услуг | C34: 5
B35: Сектор рекламы и PR | C35: 2
B36: Тендерный офис | C36: 4
A37: ЦФО Ком.служба (2 ур) Итог | C37: 36
A38: ЦФО МГС (1 ур) | B38: Азовский СЦ | C38: 3
B39: Батайский СЦ | C39: 2
B40: Вешенский СЦ | C40: 1
B41: Волгодонской СЦ | C41: 2
B42: Зерноградский СЦ | C42: 2
B43: Каменск-Шахтинский СЦ | C43: 3
...

Sheet Список уволенных
A1: Выгрузка из 1С | B1: Выгрузка из 1С | C1: Выгрузка из 1С | D1: Выгрузка из 1С | E1: Заполняем вручную, настроен выпадающий список | F1: Выгрузка из 1С | G1: Заполняем вручную, настроен выпадающий список | H1: Заполняем вручную, настроен выпадающий список | I1: Автоматическое заполнение | J1: Заполняем вручную, настроен выпадающий список | K1: Заполняем вручную, настроен выпадающий список | L1: Автоматическое заполнение, если заполнена колонка "К" | M1: Выгрузка из 1С | N1: Заполняем вручную, настроен выпадающий список | O1: Заполняем вручную, настроен выпадающий список | P1: Автоматическое заполнение | Q1: Автоматическое заполнение | R1: Автоматическое заполнение | S1: Выгрузка из 1С | T1: Заполняем вручную, настроен выпадающий список | U1: Заполняем вручную | V1: Заполняем вручную, настроен выпадающий список | W1: Заполняем вручную
A2: Таб. № | B2: ФИО | C2: Подразделение | D2: Должность | E2: Основное место работы/Совместительство | F2: Дата увольнения | G2: Категории персонала | H2: Статья ТК РФ | I2: Расшифровка статьи увольнения | J2: Месяц увольнения | K2: Реальные причины увольнения | L2: включаем \ не включаем | M2: Дата начала работы в ГК | N2: Город, фактическое место работы | O2: Тип договора | P2: Длительность работы в компании | Q2: Увольнение в течении испытательного срока | R2: Пол | S2: Дата рождения | T2: Юридическое лицо | U2: Непосредственный руководитель | V2: ЦФО | W2: ФИО рекрутера
A3: 00482 | B3: Махлин Константин Романович | C3: Руководство (основное) | D3: Директор | E3: Внешнее совместительство | F3: 28.01.2026 | H3: п. 3 части 1 ст. 77 ТК РФ | J3: Январь | K3: 3. Оптимизация структуры Компании | L3: =IF(O3="Постоянный",VLOOKUP(K3,'Включаем не включаем'!$A$1:$B$65536,2,0),"не включаем") -> не включаем | M3: 20.05.2025 | N3: Ростов-на-Дону | O3: постоянный | P3: =DAYS360(M3,F3,TRUE)/30 -> 8.2666667 | Q3: =IF(DAYS360(M3,F3,TRUE)>120,"-","увольнение в течении испытательного срока") -> - | R3: =IF(ISBLANK(B3),"-",IF(ISERROR(FIND("вич",B3,1)),"ж","м")) -> м | S3: 16.02.1978 | T3: АЛМАЗ ООО | U3: Амураль И.Б. | V3: ЦФО Производство №2 (1 ур)
A4: 01000 | B4: Пахомов Александр Борисович | C4: Сектор доработки и улучшения серийной продукции | D4: Инженер-программист 2 категории | E4: Основное место работы | F4: 26.02.2026 | H4: п. 3 части 1 ст. 77 ТК РФ | J4: Февраль | K4: 1. Предложили более высокую зарплату на аналогичной должности, неудовлетворенность текущей з/платой | L4: не включаем | M4: 05.06.2025 | N4: Ростов-на-Дону | O4: постоянный | P4: =DAYS360(M4,F4,TRUE)/30 -> 8.7 | Q4: =IF(DAYS360(M4,F4,TRUE)>120,"-","увольнение в течении испытательного срока") -> - | R4: =IF(ISBLANK(B4),"-",IF(ISERROR(FIND("вич",B4,1)),"ж","м")) -> м | S4: 10.03.1982 | T4: ТУРБУЛЕНТНОСТЬ-ДОН ООО НПО | U4: Асланян | V4: ЦФО Производство №1 (1 ур)
A5: 01078 | B5: Веровенко Юрий Александрович | C5: Сервисная служба | D5: Инженер КИПиА | E5: Основное место работы | F5: 24.02.2026 | H5: п. 3 части 1 ст. 77 ТК РФ | J5: Февраль | K5: 1. Предложили более высокую зарплату на аналогичной должности, неудовлетворенность текущей з/платой | L5: =IF(O5="Постоянный",VLOOKUP(K5,'Включаем не включаем'!$A$1:$B$65536,2,0),"не включаем") -> не включаем | M5: 08.12.2025 | N5: Ростов-на-Дону | O5: постоянный | P5: =DAYS360(M5,F5,TRUE)/30 -> 2.5333333 | Q5: =IF(DAYS360(M5,F5,TRUE)>120,"-","увольнение в течении испытательного срока") -> увольнение в течении испытательного срока | R5: =IF(ISBLANK(B5),"-",IF(ISERROR(FIND("вич",B5,1)),"ж","м")) -> м | S5: 09.12.1998 | T5: ТУРБУЛЕНТНОСТЬ-ДОН ООО НПО | U5: Гайфулин Д.А. | V5: ЦФО Сервисная служба (1+2 ур)
A6: 01071 | B6: Коротун Сергей Леонидович | C6: Служба безопасности | D6: Контролер поста контроля | E6: Основное место работы | F6: 20.02.2026 | H6: п. 3 части 1 ст. 77 ТК РФ | J6: Февраль | K6: 2. Неадекватное поведение, поступки и т.п. | L6: не включаем | M6: 24.11.2025 | N6: Ростов-на-Дону | O6: постоянный | P6: =DAYS360(M6,F6,TRUE)/30 -> 2.8666667 | Q6: =IF(DAYS360(M6,F6,TRUE)>120,"-","увольнение в течении испытательного срока") -> увольнение в течении испытательного срока | R6: =IF(ISBLANK(B6),"-",IF(ISERROR(FIND("вич",B6,1)),"ж","м")) -> м | S6: 25.01.1960 | T6: ТУРБУЛЕНТНОСТЬ-ДОН ООО НПО | U6: Гриппа Г.А. | V6: ЦФО Служба безопасности (2 ур)
A7: 01052 | B7: Чернов Александр Евгеньевич | C7: Коммерческая служба | D7: Коммерческий директор | E7: Основное место работы | F7: 26.01.2026 | H7: п. 3 части 1 ст. 77 ТК РФ | J7: Январь | K7: 1. Предложили более высокую позицию, нет карьерного роста в Компании | L7: не включаем | M7: 13.10.2025 | N7: Ростов-на-Дону | O7: постоянный | P7: =DAYS360(M7,F7,TRUE)/30 -> 3.4333333 | Q7: =IF(DAYS360(M7,F7,TRUE)>120,"-","увольнение в течении испытательного срока") -> увольнение в течении испытательного срока | R7: =IF(ISBLANK(B7),"-",IF(ISERROR(FIND("вич",B7,1)),"ж","м")) -> м | S7: 23.08.1983 | T7: ТУРБУЛЕНТНОСТЬ-ДОН ООО НПО | U7: Донцова А.Е. | V7: ЦФО Ком.служба (2 ур)
A8: 00103 | B8: Кузнецов Сергей Сергеевич | C8: Группа сопровождения продаж и производства | D8: Начальник отдела | E8: Основное место работы | F8: 20.01.2026 | H8: п. 3 части 1 ст. 77 ТК РФ | J8: Январь | K8: 2. Низкие результаты, не справляется с основными обязанностями | L8: не включаем | M8: 03.12.2018 | N8: Ростов-на-Дону | O8: постоянный | P8: =DAYS360(M8,F8,TRUE)/30 -> 85.566667 | Q8: =IF(DAYS360(M8,F8,TRUE)>120,"-","увольнение в течении испытательного срока") -> - | R8: =IF(ISBLANK(B8),"-",IF(ISERROR(FIND("вич",B8,1)),"ж","м")) -> м | S8: 08.10.1982 | T8: ТУРБУЛЕНТНОСТЬ-ДОН ООО НПО | U8: Ермаков И. | V8: ЦФО Производство №1 (1 ур)
A9: 00567 | B9: Хайрулин Михаил Шаукатович | C9: Сектор доработки и улучшения серийной продукции | D9: Инженер-конструктор 1 категории | E9: Основное место работы | F9: 11.02.2026 | H9: п. 3 части 1 ст. 77 ТК РФ | J9: Февраль | K9: 1. Предложили более высокую зарплату на аналогичной должности, неудовлетворенность текущей з/платой | L9: =IF(O9="Постоянный",VLOOKUP(K9,'Включаем не включаем'!$A$1:$B$65536,2,0),"не включаем") -> не включаем | M9: 29.08.2022 | N9: Ростов-на-Дону | O9: постоянный | P9: =DAYS360(M9,F9,TRUE)/30 -> 41.4 | Q9: =IF(DAYS360(M9,F9,TRUE)>120,"-","увольнение в течении испытательного срока") -> - | R9: =IF(ISBLANK(B9),"-",IF(ISERROR(FIND("вич",B9,1)),"ж","м")) -> м | S9: 02.11.1983 | T9: ТУРБУЛЕНТНОСТЬ-ДОН ООО НПО | U9: Емельяненко | V9: ЦФО Производство №1 (1 ур)
A10: 00837 | B10: Мальцев Дмитрий Алексеевич | C10: Экспериментальный производственный цех | D10: Слесарь КИПиА | E10: Основное место работы | F10: 28.01.2026 | H10: п. 3 части 1 ст. 77 ТК РФ | J10: Январь | K10: 1. Другая сфера деятельности, открытие собственного дела и т.п. | L10: =IF(O10="Постоянный",VLOOKUP(K10,'Включаем не включаем'!$A$1:$B$65536,2,0),"не включаем") -> не включаем | M10: 29.07.2024 | N10: Ростов-на-Дону | O10: постоянный | P10: =DAYS360(M10,F10,TRUE)/30 -> 17.966667 | Q10: =IF(DAYS360(M10,F10,TRUE)>120,"-","увольнение в течении испытательного срока") -> - | R10: =IF(ISBLANK(B10),"-",IF(ISERROR(FIND("вич",B10,1)),"ж","м")) -> м | S10: 27.10.2000 | T10: ТУРБУЛЕНТНОСТЬ-ДОН ООО НПО | U10: Зайцев Г.Н. | V10: ЦФО Производство №1 (1 ур)
A11: 00503 | B11: Матофонов Андрей Николаевич | C11: Участок монтажа радиоэлектронной аппаратуры | D11: Монтажник РЭА | E11: Основное место работы | F11: 13.01.2026 | H11: п. 3 части 1 ст. 77 ТК РФ | J11: Январь | K11: 1. Предложили более высокую зарплату на аналогичной должности, неудовлетворенность текущей з/платой | L11: =IF(O11="Постоянный",VLOOKUP(K11,'Включаем не включаем'!$A$1:$B$65536,2,0),"не включаем") -> не включаем | M11: 09.12.2025 | N11: Ростов-на-Дону | O11: постоянный | P11: =DAYS360(M11,F11,TRUE)/30 -> 1.1333333 | Q11: =IF(DAYS360(M11,F11,TRUE)>120,"-","увольнение в течении испытательного срока") -> увольнение в течении испытательного срока | R11: =IF(ISBLANK(B11),"-",IF(ISERROR(FIND("вич",B11,1)),"ж","м")) -> м | S11: 06.06.1984 | T11: АЛМАЗ ООО | U11: Зайцев Г.Н. | V11: ЦФО Производство №2 (1 ур)
A12: 00042 | B12: Сенькина Марина Александровна | C12: Отдел материально-технического обеспечения | D12: Менеджер по сопровождению | E12: Основное место работы | F12: 30.01.2026 | H12: п. 3 части 1 ст. 77 ТК РФ | J12: Январь | K12: 3. Переезд на другое место жительства | L12: =IF(O12="Постоянный",VLOOKUP(K12,'Включаем не включаем'!$A$1:$B$65536,2,0),"не включаем") -> не включаем | M12: 01.11.2025 | N12: Ростов-на-Дону | O12: постоянный | P12: =DAYS360(M12,F12,TRUE)/30 -> 2.9666667 | Q12: =IF(DAYS360(M12,F12,TRUE)>120,"-","увольнение в течении испытательного срока") -> увольнение в течении испытательного срока | R12: =IF(ISBLANK(B12),"-",IF(ISERROR(FIND("вич",B12,1)),"ж","м")) -> ж | S12: 02.09.1979 | T12: ИП Корниенко М.В. | U12: Коваленко А.О. | V12: ЦФО Служба логистики (2 ур)
A13: 00207 | B13: Будиловская Олеся Викторовна | C13: Отдел продаж | D13: Менеджер по работе с клиентами | E13: Основное место работы | F13: 09.02.2026 | H13: п. 3 части 1 ст. 77 ТК РФ | J13: Февраль | K13: 3. Перевод работника с его согласия в другое юридическое лицо в рамках Группы компаний | L13: =IF(O13="Постоянный",VLOOKUP(K13,'Включаем не включаем'!$A$1:$B$65536,2,0),"не включаем") -> не включаем | M13: 10.03.2025 | N13: Ростов-на-Дону | O13: постоянный | P13: =DAYS360(M13,F13,TRUE)/30 -> 10.966667 | Q13: =IF(DAYS360(M13,F13,TRUE)>120,"-","увольнение в течении испытательного срока") -> - | R13: =IF(ISBLANK(B13),"-",IF(ISERROR(FIND("вич",B13,1)),"ж","м")) -> ж | S13: 26.01.1984 | T13: ТД Амурская легенда | U13: Кузнецова Л.Г. | V13: ЦФО Амурская легенда (1 ур)
A14: 00243 | B14: Задорожняя Ольга Владимировна | C14: Производственный отдел | D14: Уборщик помещений | E14: Основное место работы | F14: 09.02.2026 | H14: п. 3 части 1 ст. 77 ТК РФ | J14: Февраль | K14: 1. Плохие условия труда | L14: =IF(O14="Постоянный",VLOOKUP(K14,'Включаем не включаем'!$A$1:$B$65536,2,0),"не включаем") -> не включаем | M14: 04.02.2026 | N14: Ростов-на-Дону | O14: постоянный | P14: =DAYS360(M14,F14,TRUE)/30 -> 0.16666667 | Q14: =IF(DAYS360(M14,F14,TRUE)>120,"-","увольнение в течении испытательного срока") -> увольнение в течении испытательного срока | R14: =IF(ISBLANK(B14),"-",IF(ISERROR(FIND("вич",B14,1)),"ж","м")) -> ж | S14: 22.11.1974 | T14: ТД Амурская легенда | U14: Кузнецова Л.Г. | V14: ЦФО Амурская легенда (1 ур)
A15: 00214 | B15: Адекола Фейт Адейеми | C15: Производственный отдел | D15: Упаковщик | E15: Основное место работы | F15: 02.02.2026 | H15: п. 3 части 1 ст. 77 ТК РФ | J15: Февраль | K15: 3. Переезд на другое место жительства | L15: =IF(O15="Постоянный",VLOOKUP(K15,'Включаем не включаем'!$A$1:$B$65536,2,0),"не включаем") -> не включаем | M15: 02.04.2025 | N15: Ростов-на-Дону | O15: постоянный | P15: =DAYS360(M15,F15,TRUE)/30 -> 10 | Q15: =IF(DAYS360(M15,F15,TRUE)>120,"-","увольнение в течении испытательного срока") -> - | R15: =IF(ISBLANK(B15),"-",IF(ISERROR(FIND("вич",B15,1)),"ж","м")) -> ж | S15: 27.06.1997 | T15: ТД Амурская легенда | U15: Кузнецова Л.Г. | V15: ЦФО Амурская легенда (1 ур)
A16: 00925 | B16: Литвинов Антон Викторович | C16: Склад БМИ | D16: Начальник склада | E16: Основное место работы | F16: 20.02.2026 | H16: п. 3 части 1 ст. 77 ТК РФ | J16: Февраль | K16: 1. Семейные обстоятельства | L16: =IF(O16="Постоянный",VLOOKUP(K16,'Включаем не включаем'!$A$1:$B$65536,2,0),"не включаем") -> не включаем | M16: 06.02.2025 | N16: Ростов-на-Дону | O16: постоянный | P16: =DAYS360(M16,F16,TRUE)/30 -> 12.466667 | Q16: =IF(DAYS360(M16,F16,TRUE)>120,"-","увольнение в течении испытательного срока") -> - | R16: =IF(ISBLANK(B16),"-",IF(ISERROR(FIND("вич",B16,1)),"ж","м")) -> м | S16: 14.08.1990 | T16: ТУРБУЛЕНТНОСТЬ-ДОН ООО НПО | U16: Кургин Ф.В. | V16: ЦФО Служба логистики (2 ур)
A17: 00481 | B17: Агарков Алексей Валерьевич | C17: Складской комплекс | D17: Кладовщик | E17: Основное место работы | F17: 16.02.2026 | H17: п. 3 части 1 ст. 77 ТК РФ | J17: Февраль | K17: 1. Предложили более высокую зарплату на аналогичной должности, неудовлетворенность текущей з/платой | L17: =IF(O17="Постоянный",VLOOKUP(K17,'Включаем не включаем'!$A$1:$B$65536,2,0),"не включаем") -> не включаем | M17: 01.02.2022 | N17: Ростов-на-Дону | O17: постоянный | P17: =DAYS360(M17,F17,TRUE)/30 -> 48.5 | Q17: =IF(DAYS360(M17,F17,TRUE)>120,"-","увольнение в течении испытательного срока") -> - | R17: =IF(ISBLANK(B17),"-",IF(ISERROR(FIND("вич",B17,1)),"ж","м")) -> м | S17: 29.09.1986 | T17: ТУРБУЛЕНТНОСТЬ-ДОН ООО НПО | U17: Кургин Ф.В. | V17: ЦФО Служба логистики (2 ур)
A18: 00828 | B18: Бондарь Сергей Викторович | C18: Складской комплекс | D18: Кладовщик | E18: Основное место работы | F18: 06.02.2026 | H18: п. 3 части 1 ст. 77 ТК РФ | J18: Февраль | K18: 1. Недовольство руководством, непосредственным руководителем, общим стилем управления, отношениями в отделе | L18: =IF(O18="Постоянный",VLOOKUP(K18,'Включаем не включаем'!$A$1:$B$65536,2,0),"не включаем") -> не включаем | M18: 27.06.2024 | N18: Ростов-на-Дону | O18: постоянный | P18: =DAYS360(M18,F18,TRUE)/30 -> 19.3 | Q18: =IF(DAYS360(M18,F18,TRUE)>120,"-","увольнение в течении испытательного срока") -> - | R18: =IF(ISBLANK(B18),"-",IF(ISERROR(FIND("вич",B18,1)),"ж","м")) -> м | S18: 22.01.1985 | T18: ТУРБУЛЕНТНОСТЬ-ДОН ООО НПО | U18: Кургин Ф.В. | V18: ЦФО Служба логистики (2 ур)
A19: 00120 | B19: Кондаков Михаил Михайлович | C19: Азовский СЦ | D19: Техник | E19: Основное место работы | F19: 27.01.2026 | H19: п. 3 части 1 ст. 77 ТК РФ | J19: Январь | K19: 3. Оптимизация структуры Компании | L19: =IF(O19="Постоянный",VLOOKUP(K19,'Включаем не включаем'!$A$1:$B$65536,2,0),"не включаем") -> не включаем | M19: 08.04.2024 | N19: Ростов-на-Дону | O19: постоянный | P19: =DAYS360(M19,F19,TRUE)/30 -> 21.633333 | Q19: =IF(DAYS360(M19,F19,TRUE)>120,"-","увольнение в течении испытательного срока") -> - | R19: =IF(ISBLANK(B19),"-",IF(ISERROR(FIND("вич",B19,1)),"ж","м")) -> м | S19: 03.06.1994 | T19: Метрогазсервис ООО | U19: Махлин К.Р. | V19: ЦФО МГС (1 ур)
A20: 00036 | B20: Самарина Светлана Федоровна | C20: Таганрогский СЦ | D20: Кассир-приемщик | E20: Основное место работы | F20: 04.02.2026 | H20: п. 3 части 1 ст. 77 ТК РФ | J20: Февраль | K20: 1. Недовольство руководством, непосредственным руководителем, общим стилем управления, отношениями в отделе | L20: =IF(O20="Постоянный",VLOOKUP(K20,'Включаем не включаем'!$A$1:$B$65536,2,0),"не включаем") -> не включаем | M20: 06.11.2018 | N20: Ростов-на-Дону | O20: постоянный | P20: =DAYS360(M20,F20,TRUE)/30 -> 86.933333 | Q20: =IF(DAYS360(M20,F20,TRUE)>120,"-","увольнение в течении испытательного срока") -> - | R20: =IF(ISBLANK(B20),"-",IF(ISERROR(FIND("вич",B20,1)),"ж","м")) -> ж | S20: 23.12.1970 | T20: Метрогазсервис ООО | U20: Махлин К.Р. | V20: ЦФО МГС (1 ур)
... A24: 00505 | B24: Боброва Оксана Александровна | C24: Участок сборки UFG-H | D24: Сборщик | E24: Основное место работы | F24: 27.02.2026 | H24: п. 3 части 1 ст. 77 ТК РФ | J24: Февраль | K24: 2. Низкие результаты, не справляется с основными обязанностями | L24: =IF(O24="Постоянный",VLOOKUP(K24,'Включаем не включаем'!$A$1:$B$65536,2,0),"не включаем") -> не включаем | M24: 17.12.2025 | N24: Ростов-на-Дону | O24: постоянный | P24: =DAYS360(M24,F24,TRUE)/30 -> 2.3333333 | Q24: =IF(DAYS360(M24,F24,TRUE)>120,"-","увольнение в течении испытательного срока") -> увольнение в течении испытательного срока | R24: =IF(ISBLANK(B24),"-",IF(ISERROR(FIND("вич",B24,1)),"ж","м")) -> ж | S24: 06.02.1981 | T24: АЛМАЗ ООО | U24: Сафронов И.А. | V24: ЦФО Производство №2 (1 ур)
A25: 00010 | B25: Кучер Роман Витальевич | C25: Транспортный отдел | D25: Водитель автомобиля | E25: Основное место работы | F25: 22.01.2026 | H25: п. 3 части 1 ст. 77 ТК РФ | J25: Январь | K25: 1. Предложили более высокую зарплату на аналогичной должности, неудовлетворенность текущей з/платой | L25: не включаем | M25: 02.09.2025 | N25: Ростов-на-Дону | O25: постоянный | P25: =DAYS360(M25,F25,TRUE)/30 -> 4.6666667 | Q25: =IF(DAYS360(M25,F25,TRUE)>120,"-","увольнение в течении испытательного срока") -> - | R25: =IF(ISBLANK(B25),"-",IF(ISERROR(FIND("вич",B25,1)),"ж","м")) -> м | S25: 12.11.1992 | T25: ТД Амурская легенда | U25: Сефиханов Р.И. | V25: ЦФО Амурская легенда (1 ур)
A26: 00239 | B26: Игнатенко Никита Александрович | C26: Транспортный отдел | D26: Водитель автомобиля | E26: Основное место работы | F26: 13.01.2026 | H26: п. 3 части 1 ст. 77 ТК РФ | J26: Январь | K26: 1. Предложили более высокую зарплату на аналогичной должности, неудовлетворенность текущей з/платой | L26: не включаем | M26: 15.10.2025 | N26: Ростов-на-Дону | O26: постоянный | P26: =DAYS360(M26,F26,TRUE)/30 -> 2.9333333 | Q26: =IF(DAYS360(M26,F26,TRUE)>120,"-","увольнение в течении испытательного срока") -> увольнение в течении испытательного срока | R26: =IF(ISBLANK(B26),"-",IF(ISERROR(FIND("вич",B26,1)),"ж","м")) -> м | S26: 08.01.1995 | T26: ТД Амурская легенда | U26: Сефиханов Р.И. | V26: ЦФО Амурская легенда (1 ур)
A27: 01056 | B27: Ставицкий Николай Николаевич | C27: Транспортная служба | D27: Водитель автомобиля | E27: Основное место работы | F27: 10.02.2026 | H27: п. 3 части 1 ст. 77 ТК РФ | J27: Февраль | K27: 2. Пьянство | L27: не включаем | M27: 16.10.2025 | N27: Ростов-на-Дону | O27: постоянный | P27: =DAYS360(M27,F27,TRUE)/30 -> 3.8 | Q27: =IF(DAYS360(M27,F27,TRUE)>120,"-","увольнение в течении испытательного срока") -> увольнение в течении испытательного срока | R27: =IF(ISBLANK(B27),"-",IF(ISERROR(FIND("вич",B27,1)),"ж","м")) -> м | S27: 18.10.1976 | T27: ТУРБУЛЕНТНОСТЬ-ДОН ООО НПО | U27: Сефиханов Р.И. | V27: ЦФО Служба логистики (2 ур)
A28: 00683 | B28: Иликаев Алексей Валерьевич | C28: Лаборатория неразрушающего контроля | D28: Специалист по неразрушающему контролю | E28: Основное место работы | F28: 27.02.2026 | H28: п. 3 части 1 ст. 77 ТК РФ | J28: Февраль | K28: 1. Предложили более высокую зарплату на аналогичной должности, неудовлетворенность текущей з/платой | L28: =IF(O28="Постоянный",VLOOKUP(K28,'Включаем не включаем'!$A$1:$B$65536,2,0),"не включаем") -> не включаем | M28: 17.07.2023 | N28: Ростов-на-Дону | O28: постоянный | P28: =DAYS360(M28,F28,TRUE)/30 -> 31.333333 | Q28: =IF(DAYS360(M28,F28,TRUE)>120,"-","увольнение в течении испытательного срока") -> - | R28: =IF(ISBLANK(B28),"-",IF(ISERROR(FIND("вич",B28,1)),"ж","м")) -> м | S28: 24.02.1996 | T28: ТУРБУЛЕНТНОСТЬ-ДОН ООО НПО | U28: Сливков П.Е. | V28: ЦФО Служба технического директора (2 ур)
A29: 01022 | B29: Беспалов Кирилл Алексеевич | C29: Отдел внешнеэкономической деятельности | D29: Ведущий менеджер | E29: Основное место работы | F29: 13.02.2026 | H29: п. 3 части 1 ст. 77 ТК РФ | J29: Февраль | K29: 1. Другая сфера деятельности, открытие собственного дела и т.п. | L29: =IF(O29="Постоянный",VLOOKUP(K29,'Включаем не включаем'!$A$1:$B$65536,2,0),"не включаем") -> не включаем | M29: 23.07.2025 | N29: Ростов-на-Дону | O29: постоянный | P29: =DAYS360(M29,F29,TRUE)/30 -> 6.6666667 | Q29: =IF(DAYS360(M29,F29,TRUE)>120,"-","увольнение в течении испытательного срока") -> - | R29: =IF(ISBLANK(B29),"-",IF(ISERROR(FIND("вич",B29,1)),"ж","м")) -> м | S29: 24.04.2004 | T29: ТУРБУЛЕНТНОСТЬ-ДОН ООО НПО | U29: Титова Я.В. | V29: ЦФО Ком.служба (2 ур)
A30: 00788 | B30: Елагина Мария Геннадьевна | C30: Сектор промышленной безопасности | D30: Специалист по промышленной безопасности | E30: Основное место работы | F30: 06.02.2026 | H30: п. 3 части 1 ст. 77 ТК РФ | J30: Февраль | K30: 1. Недовольство руководством, непосредственным руководителем, общим стилем управления, отношениями в отделе | L30: =IF(O30="Постоянный",VLOOKUP(K30,'Включаем не включаем'!$A$1:$B$65536,2,0),"не включаем") -> не включаем | M30: 25.03.2024 | N30: Ростов-на-Дону | O30: постоянный | P30: =DAYS360(M30,F30,TRUE)/30 -> 22.366667 | Q30: =IF(DAYS360(M30,F30,TRUE)>120,"-","увольнение в течении испытательного срока") -> - | R30: =IF(ISBLANK(B30),"-",IF(ISERROR(FIND("вич",B30,1)),"ж","м")) -> ж | S30: 16.06.1999 | T30: ТУРБУЛЕНТНОСТЬ-ДОН ООО НПО | U30: Улановский К.В. | V30: ЦФО Служба технического директора (2 ур)
A31: 00809 | B31: Федоров Юрий Робертович | C31: Сектор разработки технических решений | D31: Ведущий инженер-проектировщик АСУТП | E31: Основное место работы | F31: 03.02.2026 | H31: п. 3 части 1 ст. 77 ТК РФ | J31: Февраль | K31: 1. Предложили более высокую зарплату на аналогичной должности, неудовлетворенность текущей з/платой | L31: =IF(O31="Постоянный",VLOOKUP(K31,'Включаем не включаем'!$A$1:$B$65536,2,0),"не включаем") -> не включаем | M31: 21.05.2024 | N31: Ростов-на-Дону | O31: постоянный | P31: =DAYS360(M31,F31,TRUE)/30 -> 20.4 | Q31: =IF(DAYS360(M31,F31,TRUE)>120,"-","увольнение в течении испытательного срока") -> - | R31: =IF(ISBLANK(B31),"-",IF(ISERROR(FIND("вич",B31,1)),"ж","м")) -> м | S31: 29.01.1973 | T31: ТУРБУЛЕНТНОСТЬ-ДОН ООО НПО | U31: Улановский К.В. | V31: ЦФО Служба технического директора (2 ур)
A32: 00917 | B32: Никитаев Алексей Вячеславович | C32: Сектор по внедрению искусственного интеллекта | D32: Промт-инженер 2 категории | E32: Основное место работы | F32: 03.02.2026 | H32: п. 3 части 1 ст. 77 ТК РФ | J32: Февраль | K32: 1. Предложили более высокую зарплату на аналогичной должности, неудовлетворенность текущей з/платой | L32: не включаем | M32: 29.01.2025 | N32: Ростов-на-Дону | O32: постоянный | P32: =DAYS360(M32,F32,TRUE)/30 -> 12.133333 | Q32: =IF(DAYS360(M32,F32,TRUE)>120,"-","увольнение в течении испытательного срока") -> - | R32: =IF(ISBLANK(B32),"-",IF(ISERROR(FIND("вич",B32,1)),"ж","м")) -> м | S32: 15.04.1979 | T32: ТУРБУЛЕНТНОСТЬ-ДОН ООО НПО | U32: Ясыров Б. | V32: ЦФО Служба развития (2 ур)
A33: 00838 | B33: Белан Дмитрий Александрович | C33: Участок ЧПУ и плазмы | D33: Оператор станков с программным управлением | E33: Основное место работы | F33: 31.03.2026 | H33: п. 3 части 1 ст. 77 ТК РФ | J33: Март | K33: 2. Неадекватное поведение, поступки и т.п. | L33: не включаем | M33: 29.07.2024 | N33: Ростов-на-Дону | O33: постоянный | P33: =DAYS360(M33,F33,TRUE)/30 -> 20.033333 | Q33: =IF(DAYS360(M33,F33,TRUE)>120,"-","увольнение в течении испытательного срока") -> - | R33: =IF(ISBLANK(B33),"-",IF(ISERROR(FIND("вич",B33,1)),"ж","м")) -> м | S33: 05.05.1985 | T33: ТУРБУЛЕНТНОСТЬ-ДОН ООО НПО | U33: Князев Д. | V33: ЦФО Производство №1 (1 ур)
A34: 00824 | B34: Ткаченко Людмила Викторовна | C34: Отдел ценообразования и экономического планирования | D34: Начальник отдела | E34: Основное место работы | F34: 26.03.2026 | H34: п. 3 части 1 ст. 77 ТК РФ | J34: Март | K34: 2. Низкие результаты, не справляется с основными обязанностями | L34: не включаем | M34: 24.06.2024 | N34: Ростов-на-Дону | O34: постоянный | P34: =DAYS360(M34,F34,TRUE)/30 -> 21.066667 | Q34: =IF(DAYS360(M34,F34,TRUE)>120,"-","увольнение в течении испытательного срока") -> - | R34: =IF(ISBLANK(B34),"-",IF(ISERROR(FIND("вич",B34,1)),"ж","м")) -> ж | S34: 28.05.1977 | T34: ТУРБУЛЕНТНОСТЬ-ДОН ООО НПО | U34: Донцова А.Е. | V34: ЦФО Директор НПО (2 ур)
A35: 00682 | B35: Бабенкова Ирина Сергеевна | C35: Сектор обучения и развития | D35: Ведущий разработчик электронных курсов | E35: Основное место работы | F35: 24.03.2026 | H35: п. 3 части 1 ст. 77 ТК РФ | J35: Март | K35: 1. Неудобное расположение, далеко от дома | L35: =IF(O35="Постоянный",VLOOKUP(K35,'Включаем не включаем'!$A$1:$B$65536,2,0),"не включаем") -> не включаем | M35: 14.07.2023 | N35: Ростов-на-Дону | O35: постоянный | P35: =DAYS360(M35,F35,TRUE)/30 -> 32.333333 | Q35: =IF(DAYS360(M35,F35,TRUE)>120,"-","увольнение в течении испытательного срока") -> - | R35: =IF(ISBLANK(B35),"-",IF(ISERROR(FIND("вич",B35,1)),"ж","м")) -> ж | S35: 13.06.1987 | T35: ТУРБУЛЕНТНОСТЬ-ДОН ООО НПО | U35: Соломичева С.В. | V35: ЦФО Служба развития (2 ур)
A36: 01038 | B36: Газизов Денис Андреевич | C36: Метрологическая служба | D36: Инженер-метролог | E36: Основное место работы | F36: 23.03.2026 | H36: п. 3 части 1 ст. 77 ТК РФ | J36: Март | K36: 2. Низкие результаты, не справляется с основными обязанностями | L36: не включаем | M36: 01.09.2025 | N36: Ростов-на-Дону | O36: постоянный | P36: =DAYS360(M36,F36,TRUE)/30 -> 6.7333333 | Q36: =IF(DAYS360(M36,F36,TRUE)>120,"-","увольнение в течении испытательного срока") -> - | R36: =IF(ISBLANK(B36),"-",IF(ISERROR(FIND("вич",B36,1)),"ж","м")) -> м | S36: 26.06.1996 | T36: ТУРБУЛЕНТНОСТЬ-ДОН ООО НПО | U36: Хозуян И.В. | V36: ЦФО Главный метролог (1 ур)
A37: 00875 | B37: Шинкаренко Евгений Андреевич | C37: Производственный цех №1 | D37: Мастер участка | E37: Основное место работы | F37: 23.03.2026 | H37: п. 3 части 1 ст. 77 ТК РФ | J37: Март | K37: 2. Низкие результаты, не справляется с основными обязанностями | L37: не включаем | M37: 02.10.2024 | N37: Ростов-на-Дону | O37: постоянный | P37: =DAYS360(M37,F37,TRUE)/30 -> 17.7 | Q37: =IF(DAYS360(M37,F37,TRUE)>120,"-","увольнение в течении испытательного срока") -> - | R37: =IF(ISBLANK(B37),"-",IF(ISERROR(FIND("вич",B37,1)),"ж","м")) -> м | S37: 18.10.1989 | T37: ТУРБУЛЕНТНОСТЬ-ДОН ООО НПО | U37: Макеев А.С. | V37: ЦФО Производство №1 (1 ур)
A38: 00415 | B38: Гриппа Георгий Александрович | C38: Служба безопасности | D38: Начальник службы безопасности | E38: Основное место работы | F38: 23.03.2026 | H38: п. 3 части 1 ст. 77 ТК РФ | J38: Март | K38: 2. Низкие результаты, не справляется с основными обязанностями | L38: =IF(O38="Постоянный",VLOOKUP(K38,'Включаем не включаем'!$A$1:$B$65536,2,0),"не включаем") -> не включаем | M38: 28.04.2021 | N38: Ростов-на-Дону | O38: постоянный | P38: =DAYS360(M38,F38,TRUE)/30 -> 58.833333 | Q38: =IF(DAYS360(M38,F38,TRUE)>120,"-","увольнение в течении испытательного срока") -> - | R38: =IF(ISBLANK(B38),"-",IF(ISERROR(FIND("вич",B38,1)),"ж","м")) -> м | S38: 03.08.1984 | T38: ТУРБУЛЕНТНОСТЬ-ДОН ООО НПО | U38: Свистун С.Н. | V38: ЦФО Служба безопасности (2 ур)
